<?xml version="1.0"?>
<robot xmlns:xacro="http://www.ros.org/wiki/xacro" name="stretch_main">
  <xacro:property name="M_PI" value="3.1415926535897931" /> 

  <link
    name="base_link">
    <inertial>
      <origin
        xyz="-0.109461304328163 -0.000741018909047708 0.0914915269429946"
        rpy="0 0 0" />
      <mass
        value="1.0723782659782" />
      <inertia
        ixx="0.00310580907710135"
        ixy="1.5182848191076E-06"
        ixz="0.00041690466732394"
        iyy="0.00433798719991832"
        iyz="1.33487716258445E-05"
        izz="0.0037204727467362" />
    </inertial>
    <visual>
      <origin
        xyz="0 0 0"
        rpy="0 0 0" />
      <geometry>
        <mesh
          filename="package://stretch_description/meshes/base_link.STL" />
      </geometry>
      <material
        name="">
        <color
          rgba="0.792156862745098 0.819607843137255 0.933333333333333 1" />
      </material>
    </visual>
    <collision>
      <origin
        xyz="0 0 0"
        rpy="0 0 0" />
      <geometry>
        <mesh
          filename="package://stretch_description/meshes/base_link.STL" />
      </geometry>
    </collision>
  </link>
  
  <link
    name="link_right_wheel">
    <inertial>
      <origin
        xyz="1.25554620866719E-07 3.54748938447003E-07 0.0239581106165018"
        rpy="0 0 0" />
      <mass
        value="0.01" />
      <inertia
        ixx="0.001"
        ixy="0"
        ixz="0"
        iyy="0.001"
        iyz="0"
        izz="0.001" />
    </inertial>
    <visual>
      <origin
        xyz="0 0 0"
        rpy="0 0 0" />
      <geometry>
        <mesh
          filename="package://stretch_description/meshes/link_right_wheel.STL" />
      </geometry>
      <material
        name="">
        <color
          rgba="0.792156862745098 0.819607843137255 0.933333333333333 1" />
      </material>
    </visual>
    <collision>
      <origin
        xyz="0 0 0"
        rpy="0 0 0" />
      <geometry>
        <mesh
          filename="package://stretch_description/meshes/link_right_wheel.STL" />
      </geometry>
    </collision>
  </link>

  <!-- <joint name="joint_right_wheel" type="continuous">
    <parent link="base_link"/>
    <child link="link_right_wheel"/>
    <origin xyz="-0.003 -0.15765 0.05" rpy="-1.5707963267949 0 0"/>
    <axis xyz="0 0 1" />
  </joint> -->

  <joint name='joint_right_wheel' type='revolute'>
      <parent>base_link</parent>
      <child>link_right_wheel</child>
      <axis>
          <xyz expressed_in='__model__'>0 1 0</xyz> <!--can be descired to any frame or even arbitrary frames-->
          <limit>
              <lower>-1.79769e+308</lower>    <!--negative infinity-->
              <upper>1.79769e+308</upper>     <!--positive infinity-->
          </limit>
      </axis>
  </joint>

  <link
    name="link_left_wheel">
    <inertial>
      <origin
        xyz="1.2555462092223E-07 -3.54748938502514E-07 -0.0239581106165035"
        rpy="0 0 0" />
      <mass
        value="0.01" />
      <inertia
        ixx="0.001"
        ixy="0"
        ixz="0"
        iyy="0.001"
        iyz="0"
        izz="0.001" />
    </inertial>
    <visual>
      <origin
        xyz="0 0 0"
        rpy="0 0 0" />
      <geometry>
        <mesh
          filename="package://stretch_description/meshes/link_left_wheel.STL" />
      </geometry>
      <material
        name="">
        <color
          rgba="0.792156862745098 0.819607843137255 0.933333333333333 1" />
      </material>
    </visual>
    <collision>
      <origin
        xyz="0 0 0"
        rpy="0 0 0" />
      <geometry>
        <mesh
          filename="package://stretch_description/meshes/link_left_wheel.STL" />
      </geometry>
    </collision>
  </link>

  <!-- <joint name="joint_left_wheel" type="continuous">
    <parent link="base_link"/>
    <child link="link_left_wheel"/>
    <origin xyz="-0.003 0.15765 0.05" rpy="-1.5707963267949 0 0"/>
    <axis xyz="0 0 1" />
  </joint> -->

  <joint name='joint_left_wheel' type='revolute'>
      <parent>base_link</parent>
      <child>link_left_wheel</child>
      <axis>
          <xyz expressed_in='__model__'>0 1 0</xyz> <!--can be descired to any frame or even arbitrary frames-->
          <limit>
              <lower>-1.79769e+308</lower>    <!--negative infinity-->
              <upper>1.79769e+308</upper>     <!--positive infinity-->
          </limit>
      </axis>
  </joint>

  <link name="caster_link">
    <collision>
      <geometry>
        <sphere radius="0.032"/>
      </geometry>
      <origin rpy="0 0 0" xyz="0 0 0"/>
      <surface>
        <friction>
          <ode>
            <mu>0</mu>
            <mu2>0</mu2>
            <slip1>1.0</slip1>
            <slip2>1.0</slip2>
          </ode>
        </friction>
      </surface>
    </collision>
    <visual>
      <origin
        xyz="0 0 0"
        rpy="0 0 0" />
      <geometry>
        <mesh
          filename="package://stretch_description/meshes/omni_wheel_m.STL" />
      </geometry>
      <material
        name="">
        <color
          rgba="0.792156862745098 0.819607843137255 0.933333333333333 1" />
      </material>
    </visual>
    <inertial>
      <mass value="0.01" />
      <origin xyz="0 0 0" />
      <inertia
        ixx="0.001"
        ixy="0"
        ixz="0"
        iyy="0.001"
        iyz="0"
        izz="0.001" />
    </inertial>
  </link>

  <!-- <joint name="caster_joint" type="fixed">
    <parent link="base_link"/>
    <child link="caster_link"/>
    <origin xyz="-0.245 0.0 0.032" rpy="${-M_PI/2} 0 0"/>
    <axis xyz="0 0 1" />
  </joint> -->

    <joint name='caster_wheel' type='ball'>
        <parent>chassis</parent>
        <child>caster</child>
    </joint>

  <link
    name="link_mast">
    <inertial>
      <origin
        xyz="0.00755818572975822 0.773971284176834 0.00647313086620024"
        rpy="0 0 0" />
      <mass
        value="0.749143203376401" />
      <inertia
        ixx="0.0709854511954588"
        ixy="-0.00433428742758457"
        ixz="-0.000186110788697573"
        iyy="0.000437922053342648"
        iyz="-0.00288788257713431"
        izz="0.071104808501661" />
    </inertial>
    <visual>
      <origin
        xyz="0 0 0"
        rpy="0 0 0" />
      <geometry>
        <mesh
          filename="package://stretch_description/meshes/link_mast.STL" />
      </geometry>
      <material
        name="">
        <color
          rgba="0.792156862745098 0.819607843137255 0.933333333333333 1" />
      </material>
    </visual>
    <collision>
      <origin
        xyz="0 0 0"
        rpy="0 0 0" />
      <geometry>
        <mesh
          filename="package://stretch_description/meshes/link_mast.STL" />
      </geometry>
    </collision>
  </link>
  
  <joint
    name="joint_mast"
    type="fixed">
    <origin
      xyz="-0.07 0.134999999999998 0.0284000000000001"
      rpy="1.5707963267949 0 0.00925318926571245" />
    <parent
      link="base_link" />
    <child
      link="link_mast" />
    <axis
      xyz="0 0 0" />
  </joint>

</robot>